Workbook

Sheet 180-Operations
A1: Dept 180 Operations & Admin
A2: ACCOUNT | C2: 2021 | D2: 2022 | E2: 2022 | F2: 2023 YTD | G2: 2023 | H2: 2024 | I2: 2024 | J2: 45870 | K2: 2025 | L2: 2026 | M2: 2027
A3: NUMBER | B3: DESCRIPTION | C3: Budget | D3: Actual | E3: BUDGET | F3: ACTUAL | G3: BUDGET | H3: Actuals | I3: Budget | J3: YTD | K3: Budget | L3: Budget | M3: Budget | N3: 2025 Notes | O3: 2026 Notes
A5: REVENUES
A7: 3000 | B7: Regular Member Dues | C7: 839866.2 | D7: 821864.48 | E7: 839992.95 | F7: 807833.16 | G7: 864248.83 | H7: 808732.58 | I7: 867732.73 | J7: 966025 | K7: 1081620.1 | L7: 1050000 | M7: =L7*1.05 -> 1102500 | N7: Took out associates | O7: $100000 below budget in 2025; with a strong member recruitment program the numbers will grow. Looking at growth of 15 new member a month
A8: 3002 | B8: Regular New | C8: 162285 | D8: 169545 | E8: 150232.5 | F8: 208297.06 | G8: 206545.5 | H8: 223055 | I8: 195743.59 | N8: Missing $200K from Premier Membership | U8: Michael McVety
A9: 3005 | B9: Support Renewal | C9: 13066.3 | D9: 11868.22 | E9: 15120 | F9: 12742.88 | G9: 12472.11 | H9: 13395.38 | I9: 13698.6 | O9: support staff membership is no longer available | U9: Angela Holman
A10: 3007 | B10: Support New | C10: 6150 | D10: 7375 | E10: 6000 | F10: 6400 | G10: 8452.5 | H10: 5975 | I10: 6208.13 | O10: support staff membership is no longer available | U10: Donna
A11: 3008 | B11: Associate Member Dues | J11: 90480 | K11: 107445 | L11: 90500 | M11: 90500 | O11: Grandfathered membership classification | U11: Christy Ward
A12: 3010 | B12: Affiliate Member Dues | C12: 27366.9 | D12: 34214.16 | E12: 28900 | F12: 30682.98 | G12: 35722.3 | H12: 31619.16 | I12: 32984.2 | J12: 53807.5 | K12: 51965 | L12: 55000 | M12: =L12*1.05 -> 57750 | N12: 7% inc | U12: Troy Garrett
A13: 3012 | B13: Affiliate New | C13: 11955 | D13: 8330 | E13: 8845 | F13: 15730 | G13: 13324.5 | H13: 18130 | I13: 15329.5 | U13: Vicki Gaskill
A14: 3014 | B14: International Member Dues | C14: 1225 | D14: 1254.58 | E14: 1470 | F14: 1701.64 | G14: 1317.31 | H14: 1926.22 | I14: 1829.26 | J14: 2620 | K14: 2804.875 | L14: 2620 | M14: =L14*1.05 -> 2751 | U14: DD
A15: 3016 | B15: International New | C15: 245 | D15: 245 | E15: 245 | F15: 735 | G15: 771.75 | H15: 0 | I15: 526.75 | U15: Melissa
A16: 3020 | B16: Company Membership Dues | C16: 179055.32 | D16: 213462.36 | E16: 172651.5 | F16: 208887.68 | G16: 220810.46 | H16: 202610.02 | I16: 222974.01 | J16: 223450 | K16: 205200 | L16: 225000 | M16: =L16*1.05 -> 236250 | U16: Blake Hedgeman
A17: 3021 | B17: Add'l Member Dues | C17: 41697.75 | D17: 51298 | E17: 35730 | F17: 51400 | G17: 54498.15 | H17: 43345 | I17: 53965 | J17: 59475 | K17: 59968.75 | L17: 59500 | M17: =L17*1.05 -> 62475 | O17: Extra company members
A18: 3022 | B18: Add'l Support Member Dues | C18: 8714 | D18: 11502 | E18: 10100 | F18: 14100 | G18: 11552.1 | H18: 11152.84 | I18: 14835 | O18: support staff no longer available | U18: Monthly financials typically available bu the 15th of the month.
A19: 3023 | B19: Add'l Assoc. Member Dues | C19: 3920 | D19: 2240 | E19: 2362.5 | F19: 1820 | G19: 2352 | H19: 1960 | I19: 1956.5 | J19: 1980 | K19: 2037.75 | L19: 1980 | M19: 1980
B20: Total Dues Revenue | C20: 1295546.5 | D20: 1333198.8 | E20: =SUM(E7:E19) -> 1271649.4 | F20: 1360330.4 | G20: 1432067.5 | H20: =SUM(H7:H19) -> 1361901.2 | I20: =SUM(I7:I19) -> 1427783.3 | J20: =SUM(J7:J19) -> 1397837.5 | K20: =SUM(K7:K19) -> 1511041.5 | L20: =SUM(L7:L19) -> 1484600 | M20: =SUM(M7:M19) -> 1554206
N21: With $25 dues increase should increase revenues $105825
A22: Other Revenue
A24: 3125 | B24: Interest & Dividend Income | C24: 78294.16 | D24: 90880.95 | E24: 35000 | F24: 116420.72 | G24: 40000 | H24: 264313.91 | I24: 50000 | J24: 155104.6 | K24: 150000 | L24: 150000 | M24: 150000 | O24: interest rates coming down.
A25: 3127 | B25: Gain/Loss Investments | F25: 23272.08 | G25: 0 | H25: 53162.52 | I25: 0 | J25: 38741.97 | K25: 35000 | O25: We do not budget for unrealized gains/losses
A26: 3128 | B26: Unrealized Gain/Loss On Investment | F26: 0 | H26: 0 | I26: 0
A27: 3140 | B27: Miscellaneous | C27: 3212.87 | D27: 0 | E27: 100 | F27: 50 | G27: 0 | H27: 1725 | I27: 0 | J27: 0 | K27: 1000 | L27: 750
A28: 3145 | B28: Royalties | C28: 432123.49 | D28: 404969.49 | E28: 375000 | F28: 427093.8 | G28: 400000 | H28: 546379.02 | I28: 450000 | J28: 283073.13 | K28: 450000 | L28: 450000 | M28: 475000 | O28: Based on Home Depot Royalties Projections
A29: 3146 | B29: Annual Partnership Sponsorship | C29: 115000 | D29: 72000 | E29: 70000 | F29: 93000 | G29: 77000 | H29: 100991.68 | I29: 93000 | J29: 112000 | K29: 93000 | L29: 159000 | M29: =L29*1.05 -> 166950 | N29: ## partners were billed $27500 broken down as follows. $7000 NARPM Official Partner, $10,000.00 Convention Partner, $3000.00 Broker Owner Partner, $5,000.00 Residential Partner, $500.00 Communication Partner, $2000 Legislative partner | O29: 17 partners were billed $27500 broken down as follows. $7000 NARPM Official Partner, $10,000.00 Convention Partner, $3000.00 Broker Owner Partner, $5,000.00 Residential Partner, $500.00 Communication Partner, $2000 Legislative partner; 4 premier partners $10000 official partner $17000 convention partner; $12000 Broker Owner partner; $7500.00 Residential Partner, $500.00 Communication Partner, $3000 Legislative part
A30: 3147 | B30: Grievance Income | H30: 300 | I30: 0 | J30: 100 | K30: 0
A31: 3150 | B31: Prior Year Revenue | F31: 12903 | H31: 9325.43 | I31: 0 | K31: 0
B32: Other Revenue | C32: 628630.52 | D32: 567850.44 | E32: =SUM(E25:E29) -> 445100 | F32: =SUM(F24:F31) -> 672739.6 | G32: 517000 | H32: =SUM(H24:H31) -> 976197.56 | I32: =SUM(I24:I31) -> 593000 | J32: =SUM(J24:J31) -> 589019.7 | K32: =SUM(K24:K31) -> 729000 | L32: =SUM(L24:L31) -> 759750 | M32: =SUM(M24:M31) -> 791950
B34: OPERATING REVENUE | C34: 1924177 | D34: 1901049.2 | E34: =SUM(E32+E21) -> 445100 | F34: 1641306 | G34: 1949067.5 | H34: =H32+H20 -> 2338098.8 | I34: =I32+I20 -> 2020783.3 | J34: =J32+J20 -> 1986857.2 | K34: =K32+K20 -> 2240041.5 | L34: =L32+L20 -> 2244350 | M34: =M32+M20 -> 2346156
A36: EXPENSES
A38: Committee Support
A40: 5135 | B40: Board Meetings | C40: 6488.96 | D40: 11118.54 | E40: 8125 | F40: 4120.17 | G40: 14000 | H40: 6474.74 | I40: 14000 | J40: 16514.25 | K40: 10000 | L40: 16000 | M40: 16500
A41: 5136 | B41: Other Board Expense | C41: 8954.67 | D41: 14163.03 | E41: 24725 | F41: 14387.99 | G41: 20825 | H41: 10565.5 | I41: 21900 | J41: 17346.25 | K41: 15000 | L41: 20000 | M41: 21000
A42: 5138 | B42: Finance Committee | C42: 0 | D42: 0 | E42: 50 | F42: 0 | G42: 50 | H42: 0 | I42: 50 | J42: 0 | K42: 50 | L42: 0
A43: 5140 | B43: Professional Standards Committee | C43: 0 | D43: 0 | E43: 50 | F43: 0 | G43: 50 | H43: 0 | I43: 50 | J43: 0 | K43: 50 | L43: 0
A44: 5141 | B44: Nominating Committee | C44: 0 | D44: 0 | E44: 50 | F44: 0 | G44: 50 | H44: 0 | I44: 50 | J44: 0 | K44: 50 | L44: 0
A45: 5146 | B45: Ad Hoc | D45: 0 | E45: 4000 | F45: 181.11 | G45: 100 | H45: 840 | I45: 3000 | J45: 0 | K45: 3000 | L45: 1000 | M45: 1000
A46: 5156 | B46: Technology Committee | C46: 5311.16 | D46: 0 | E46: 50 | F46: 0 | G46: 5000 | H46: 0 | I46: 0 | K46: 0 | M46: 0 | N46: Have separate department budget | O46: Committee dissolved at end of 2025
B47: Total Committee Support | C47: 20754.79 | D47: 25281.57 | E47: =SUM(E40:E46) -> 37050 | F47: 18689.27 | G47: 40075 | H47: =SUM(H40:H46) -> 17880.24 | I47: =SUM(I40:I46) -> 39050 | J47: =SUM(J40:J46) -> 33860.5 | K47: =SUM(K40:K46) -> 28150 | L47: =SUM(L40:L46) -> 37000 | M47: =SUM(M40:M46) -> 38500
...

Sheet 181-Member Services
A1: Dept 181 Member Services Committee
A2: ACCOUNT | C2: 2021 | D2: 2022 | E2: 2022 | F2: 2023 | G2: 2023 | H2: 2024 | I2: 2024 | J2: 45870 | K2: 2025 | L2: 2026 | M2: 2027 | N2: 2025 Notes | O2: 2026 Notes | P2: 2027 notes
A3: NUMBER | B3: DESCRIPTION | C3: Budget | D3: Actuals | E3: Budget | F3: ACTUAL | G3: BUDGET | H3: Actual | I3: BUDGET | J3: YTD | K3: Budget | L3: Budget | M3: Budget
A4: REVENUES
A6: EXPENSES
A7: 5000 | B7: Membership Services | C7: 1099.95 | D7: 0 | E7: 3000 | F7: 0 | G7: 3000 | H7: 1584.23 | I7: 2500 | K7: 3000 | L7: 3000 | M7: 3000 | N7: Travel Committee Chair | O7: Travel Committee Chair | P7: This committee chair does not travel, delete $3,000
A8: 5005 | B8: Awards & Recognition | C8: 2189.58 | D8: 3019.87 | E8: 5000 | F8: 8951.31 | G8: 4500 | H8: 5084.47 | I8: 4250 | K8: 5000 | L8: 5100 | M8: =L8*1.3 -> 6630 | N8: includes NARPM pins | O8: includes NARPM pins | P8: inrease by inflation
A9: 5007 | B9: Affiliates Advisory Council | C9: 0 | D9: 0 | E9: 350 | F9: 0 | G9: 350 | H9: 0 | I9: 350 | K9: 150 | L9: 150 | M9: 150
A10: 5210 | B10: Postage | C10: 2868.95 | D10: 6419.21 | E10: 5000 | F10: 6724.72 | G10: 5125 | H10: 5663.58 | I10: 8500 | J10: 4401.18 | K10: 8500 | L10: 8500 | M10: =L10*1.03 -> 8755 | O10: increase in postage and member growth
A11: 5225 | B11: Printing | C11: 6325.17 | D11: 1573.21 | E11: 7000 | F11: 1676.04 | G11: 7500 | H11: 2463.98 | I11: 3000 | J11: 4559.99 | K11: 3000 | L11: 6900 | M11: =L11*1.03 -> 7107
A12: 5240 | B12: Management Fee | C12: 47208.31 | D12: 75825 | E12: =58350+120600 -> 178950 | F12: 101100 | G12: 114139.04 | H12: 117563.16 | I12: 117563.21 | J12: 80726.72 | K12: ='[2]Management Fees'!J10 -> 121090.1 | L12: =K12*1.03 -> 124722.8 | M12: =L12*1.03 -> 128464.48
A13: 5286 | B13: Gift Certificates Redeemed | C13: 0 | D13: 0 | E13: 1000 | F13: 0 | G13: 500 | H13: 0 | I13: 500 | K13: 250 | L13: 0 | M13: 0
A14: 5295 | B14: New Chapter Expenses | C14: 1477 | D14: 3132 | E14: 4000 | F14: 3132 | G14: 4000 | H14: 4732.9 | I14: 4500 | K14: 4000 | L14: 4000 | M14: 4000
A15: 5296 | B15: Chapter Grants | C15: 7466.45 | D15: 3345.14 | E15: 12000 | F15: 7345.14 | G15: 12000 | H15: 10690.57 | I15: 12000 | J15: 4222.75 | K15: 12000 | L15: 16000 | M15: 16000 | N15: Chapter Growth & Advertising Grants | O15: Chapter Growth & Advertising Grants
A16: 5297 | B16: Trade Show Grants | C16: 1000 | D16: 500 | E16: 10000 | F16: 4397 | G16: 10000 | H16: 3691.95 | I16: 8000 | J16: 150 | K16: 5000 | L16: 7500 | M16: 7500 | N16: Chapter Trade Show Grant amount reduced to $750 from $1,000. | O16: 10 Chapter Trade Show Grants @ $750 each
A17: 5298 | B17: Leadership Grant | C17: 0 | D17: -500 | E17: 7000 | F17: 0 | G17: 0 | N17: Moved to chapter leader training
A18: 5362 | B18: Chapter Incentives | C18: 30310 | D18: 38670 | E18: 42000 | F18: 38670 | G18: 42000 | H18: 30880 | I18: 42000 | J18: 23370 | K18: 40000 | L18: 35000 | M18: =L18*1.03 -> 36050 | O18: 3852 members as of March 10, 2025 under Chapters that are eligible to receive incentives (State Chapters are not eligible to receive incentives.) @ $10 each with 100% renewal. Chapters must achieve 90% or higher retention to be eligible and will receive income for new and renewed members. | P18: Angela suggested $20/member
A19: 5366 | B19: Trade Shows | C19: 91.25 | D19: 0 | E19: 9000 | F19: 0 | G19: 9000 | H19: 500 | I19: 12000 | K19: 15000 | L19: 15000 | M19: 15000 | N19: NARPM participate in 3 vendor events/trade shows to market NARPM - PE. Treas. And Staff | O19: NARPM participate in 3 vendor events/trade shows to market NARPM - PE. Treas. And Staff
A20: 5367 | B20: Trade Show Booth Purchase | C20: 0 | D20: 811.96 | E20: 1200 | F20: 811.96 | G20: 1200 | H20: 0 | I20: 1200 | J20: 699.6 | K20: 1000 | L20: 1200 | M20: 1400 | N20: Pull up banners for chapters | O20: Pull up banners for chapters
A21: 5481 | B21: Existing Technology Contracts | C21: 16920 | D21: 16129.98 | E21: 16900 | F21: 16423.98 | G21: 17000 | H21: 15551 | I21: 20000 | J21: 9944.64 | K21: 20000 | L21: 20000 | M21: 20000
A22: 5483 | B22: At Large Chapter Operations | D22: 0 | F22: 0 | G22: 3000 | H22: 0 | I22: 3500 | K22: 2000 | L22: 2000 | M22: 2000 | N22: quarterly meetings. If speakers should charge
A23: 5485 | B23: Special projects | D23: 5000 | F23: 5000 | G23: 0 | H23: 52100 | I23: 50000 | K23: 10000 | N23: special projects that arise in 2025
B24: TOTAL EXPENSES | C24: 116956.66 | D24: 153926.37 | E24: =SUM(E7:E21) -> 302400 | F24: 194232.15 | G24: 233314.04 | H24: =SUM(H7:H23) -> 250505.84 | I24: =SUM(I7:I23) -> 289863.21 | J24: =SUM(J7:J23) -> 128074.88 | K24: =SUM(K7:K23) -> 249990.1 | L24: =SUM(L6:L23) -> 249072.8 | M24: =SUM(M6:M23) -> 256056.48
B26: OPERATING PROFIT/LOSS | C26: -116956.66 | D26: -153926.37 | E26: =SUM(-E24) -> -302400 | F26: -194232.15 | G26: -233314.04 | H26: =-H24 -> -250505.84 | I26: =-I24 -> -289863.21 | J26: =-J24 -> -128074.88 | K26: =-K24 -> -249990.1 | L26: =-L24 -> -249072.8 | M26: =-M24 -> -256056.48

Sheet 182-Convention
A1: Dept 182 Convention | N1: 2025 Notes | O1: 2026 Notes
A2: ACCOUNT | C2: 2021 | D2: 2022 | E2: 2022 | F2: 2023 | G2: 2023 | H2: 2024 | I2: 2024 | J2: 45870 | K2: 2025 | L2: 2026 | M2: 2027
A3: NUMBER | B3: DESCRIPTION | C3: Budget | D3: Actuals | E3: BUDGET | F3: ACTUAL | G3: BUDGET | H3: Actuals | I3: Budget | J3: YTD | K3: Budget | L3: Budget | M3: Budget
A4: REVENUES
A5: 3146 | B5: Official Partner | C5: 50000 | D5: 108000 | E5: 50000 | F5: 138000 | G5: 130000 | H5: 160500 | I5: =(13*10000)+2500 -> 132500 | K5: =13*10000 -> 130000 | L5: 212500 | M5: 212500 | N5: 13 partners @ $10,000 plus $2500 added for PlanOmatic sponsor | O5: 17 Partners at $12,500- not including premier partnership
A6: 3400 | B6: Advertising | D6: 1567.5 | F6: 1482 | H6: 550 | I6: 0 | J6: 160 | K6: 0 | L6: 0 | M6: 0
A7: 3700 | B7: Registrations | C7: 1507.5 | D7: 699846 | E7: 357000 | F7: 488508 | G7: 447000 | H7: 490625 | I7: =(550*745)+(50*850) -> 452250 | K7: 474100 | L7: 550000 | M7: 500000 | N7: 550 registrants @ $790 40 nonmembers $990 | O7: Please note food & beverage costs for vegas. We should consider raising registration prices. I didn’t show a cost increase in the registration in the budget. this reflects a 5% increase (proposed by committee chair) to reflect the increase in value. $830
A8: 3707 | B8: Past President Event Charity | C8: 13100 | D8: 22775 | E8: 15000 | F8: 11475 | G8: 15000 | H8: 41350 | I8: =100*150 -> 15000 | K8: =150*150 -> 22500 | L8: 15000 | M8: 15000 | N8: 100 participants @ $150 | O8: 100 participants @ $150
A9: 3710 | B9: Sponsorships | C9: 66900 | D9: 66225 | E9: 75000 | F9: 110225 | G9: 83000 | H9: 72735.9 | I9: 70000 | K9: 80000 | L9: 120000 | M9: 100000 | N9: in 2024 exceeded sponsor budget so increased 2025 | O9: Increasing sponsorships for new activations - probably need some food and beverage sponsors. Exceeded 2024 & 2025 budget.
A10: 3718 | B10: Meal Tickets | C10: 0 | D10: 0 | E10: 2000 | F10: 2955 | G10: 2000 | H10: 570 | I10: 1500 | K10: 600 | L10: 0 | M10: 0 | N10: Reduced to $600 | O10: leaving meal tickets out - ideally we will just charge extra for exhibitor booth registration.
A11: 3721 | B11: Promotional Material; | D11: 5000
A12: 3723 | B12: Single Day Tickets | C12: 0 | D12: 0 | E12: 7500 | F12: 0 | G12: 5000 | H12: 0 | I12: 2500 | K12: 2500 | L12: 18000 | M12: 18000 | O12: 30 at $600
A13: 3760 | B13: Exhibit Booths | C13: 115800 | D13: 173475 | E13: 120000 | F13: 239800 | G13: 85750 | H13: 321500 | I13: =(42*2250) + (10*3100) -> 125500 | K13: =(85*2900)+(15*3300) -> 296000 | L13: 500000 | M13: 500000 | N13: Raise booth fees $2900 to include 2 meal packages; $3300 for non members | O13: 100 booths at $5,000 Depends on size of exhibitor hall - need to discuss raising prices to include meals. Increase in price is reflected in buget (was $2,900 in 2025).
B14: TOTAL REVENUES | C14: 547607.5 | D14: 1076888.5 | E14: =SUM(E5:E13) -> 626500 | F14: 992445 | G14: 767750 | H14: =SUM(H5:H13) -> 1087830.9 | I14: =SUM(I5:I13) -> 799250 | J14: =SUM(J5:J13) -> 160 | K14: =SUM(K5:K13) -> 1005700 | L14: =SUM(L5:L13) -> 1415500 | M14: =SUM(M5:M13) -> 1345500
A16: EXPENSES
A17: 5147 | B17: Convention Committee | C17: 1452.63 | D17: 958.05 | E17: 1200 | F17: 3077.7 | G17: 1500 | H17: 787.2 | I17: 1500 | K17: 1500 | L17: 1500 | M17: 1500 | N17: Committee Chair hotel | O17: Committee Chair hotel
A18: 5210 | B18: Postage | C18: 0 | D18: 0 | E18: 250 | F18: 0 | G18: 500 | H18: 160.85 | I18: 250 | K18: 200 | L18: 200 | M18: 200
A19: 5211 | B19: Shipping | C19: 0 | D19: 8324.13 | E19: 7500 | F19: 9519.53 | G19: 7500 | H19: 8284.76 | I19: 8500 | K19: 5734 | L19: 6500 | M19: 6500
A20: 5220 | B20: Supplies | C20: 568.08 | D20: 2322.7 | E20: 1000 | F20: 921.99 | G20: 2500 | H20: 3085.58 | I20: 2500 | K20: 2600 | L20: 2500 | M20: 2500 | N20: sponsor napkins, lanyards, napkins, ribbons
A21: 5221 | B21: Registration Bag | C21: 2050.44 | D21: 4026.92 | E21: 2500 | F21: 3508.59 | G21: 2500 | H21: 1125.22 | I21: 3000 | K21: 0 | L21: 0 | M21: 0 | O21: We don't do these anymore.
A22: 5225 | B22: Printing | C22: 3781.78 | D22: 2930.74 | E22: 2000 | F22: 3174.18 | G22: 4000 | H22: 1838.36 | I22: 3500 | K22: 3000 | L22: 3000 | M22: 3000
A23: 5230 | B23: Insurance | C23: 0 | D23: 3000 | E23: 3000 | F23: 0 | G23: 3300 | H23: 3501.88 | I23: 3700 | K23: 3700 | L23: 3800 | M23: 3800
A24: 5245 | B24: Attrition | C24: 43094.69 | D24: 0 | E24: 0 | G24: 0 | I24: 0 | K24: 0
A25: 5270 | B25: Miscellaneous | C25: 0 | D25: 4326.5 | E25: 1000 | F25: 100 | G25: 1500 | H25: 0 | I25: 1500 | K25: 1500 | L25: 1500 | M25: 1500
A26: 5280 | B26: Travel | C26: 7610 | D26: 11008.2 | E26: 11000 | F26: 10872.58 | G26: 12000 | H26: 15485.87 | I26: 12000 | K26: 12000 | L26: 15000 | M26: 15000 | N26: Staff travel | O26: expect an increase in travel costs overall.
A27: 5300 | B27: Audio/Visual Rental | C27: 58577.29 | D27: 127322.12 | E27: 75000 | F27: 103978.96 | G27: 105000 | H27: 125685.58 | I27: 105000 | K27: 112034 | L27: 130000 | M27: 130000
A28: 5305 | B28: Convention Video Taping Exp | C28: 30000 | D28: 20950 | E28: 15000 | F28: 20325 | G28: 25000 | H28: 29097.3 | I28: 25000 | K28: 22724 | L28: 20000 | M28: 20000 | O28: Will get quote from Everessi
A29: 5316 | B29: Temporary Service/Hotel Contract facilitator | C29: 0 | D29: 9629.85 | E29: 1000 | F29: 10201.28 | G29: 7500 | H29: 5789.34 | I29: 7500 | K29: 10000 | L29: 10000 | M29: 10000 | N29: 3rd party Hotel contractor | O29: 3rd party Hotel contractor
A30: 5320 | B30: Entertainment | C30: 250 | D30: 318 | E30: 1000 | F30: 0 | G30: 1500 | H30: 0 | I30: 1500 | K30: 1500 | L30: 10000 | M30: 10000
A31: 5323 | B31: Signage | C31: 0 | D31: 0 | E31: 2000 | F31: 0 | G31: 3500 | H31: 0 | I31: 4500 | K31: 1500 | L31: 10000 | M31: 10000 | O31: Larger hotel, convention is up escalators. - Megan is thinking treasure map vibes.
A32: 5327 | B32: Communications | H32: 49
A33: 5328 | B33: Exhibit Expenses | C33: 1014.82 | D33: 15695.15 | E33: 15000 | F33: 15220.34 | G33: 25000 | H33: 25426.9 | I33: 25000 | K33: 24085 | L33: 25000 | M33: 25000
A34: 5329 | B34: Photographer | C34: 6700 | D34: 3429.41 | E34: 5000 | F34: 6327.7 | G34: 7500 | H34: 0 | I34: 7500 | K34: 3250 | L34: 4000 | M34: 4000 | O34: Will get quote from Everessi
A35: 5335 | B35: Food and Beverage | C35: 245964.79 | D35: 595735.91 | E35: 320000 | F35: 334380.23 | G35: 375000 | H35: 644592.79 | I35: =(600*500)+(130*350) -> 345500 | K35: 525000 | L35: 736326.25 | M35: 550000 | O35: Minimum is 550,000 + 19% (non tax) gratuity, + 6% service charge + 8.375% sales tax
A36: 5354 | B36: Past President Charity Event | C36: 7545.55 | D36: 20555.98 | E36: 12000 | F36: 11275.56 | G36: 15000 | H36: 41350 | I36: 15000 | K36: 22500 | N36: Balance $0 with 182-3707 | O36: venue is not selected for 2026 yet.
A37: 5370 | B37: Facility Charge | C37: 0 | D37: =1313.75+23.51 -> 1337.26 | E37: 1500 | F37: 0 | G37: 2500 | H37: 10898.03 | I37: 2500 | K37: 7500 | L37: 7500 | M37: 7500 | N37: Room rental charges | O37: room rental charges + hotel fedex holding fees
A38: 5372 | B38: Site Inspection | D38: 3830.47 | F38: 776.45 | G38: 500 | H38: 881.75 | I38: 750 | L38: 0 | M38: 0 | O38: We do this separately for the summer board meeting.
A39: 5380 | B39: Speaker/Instructors Fee | C39: 45100 | D39: 83607.95 | E39: 75000 | F39: 77500 | G39: 75000 | H39: 42000 | I39: 75000 | K39: 75000 | L39: 85000 | M39: 85000 | O39: Member speakers get comped registration as of 2025.
A40: 5381 | B40: Speaker/Instructor Expenses | C40: 5718.42 | D40: 7000 | E40: 6000 | F40: 2731.08 | G40: 6000 | H40: 6474.48 | I40: 7000 | K40: 3664 | L40: 5000 | M40: 5000
A41: 5395 | B41: Opening Celebration | C41: 93.5 | D41: 65705.84 | F41: 68701.25 | G41: 66000 | H41: 80240.32 | I41: 68000 | K41: 72000 | L41: 100000 | M41: 100000 | O41: Most of the cost for this is food & beverage. I only put the cost for additional entertainment here.
...

Sheet 185-Ch Leader Training
A1: Dept 185 Chapter Leader Training | N1: 2025 Notes | O1: 2026 Notes
A2: ACCOUNT | C2: 2021 | D2: 2022 | E2: 2022 | F2: 2023 | G2: 2023 | H2: 2024 | I2: 2024 | J2: 45870 | K2: 2025 | L2: 2026 | M2: 2027
A3: NUMBER | B3: DESCRIPTION | C3: Budget | D3: Actuals | E3: Budget | F3: ACTUAL | G3: BUDGET | H3: Actuals | I3: Budget | J3: YTD | K3: Budget | L3: Budget | M3: Budget
A4: REVENUES
A6: EXPENSES
A7: 5210 | B7: Postage | C7: 0 | D7: 0 | E7: 250 | F7: 0 | G7: 250 | H7: 0 | I7: 150 | K7: 0 | L7: 0 | M7: 0
A8: 5220 | B8: Supplies | C8: 0 | D8: 0 | E8: 125 | F8: 0 | G8: 125 | H8: 0 | I8: 100 | K8: 100 | L8: 100 | M8: 100
A9: 5225 | B9: Printing | C9: 4112 | D9: 2560.43 | E9: 4500 | F9: 1132.46 | G9: 4500 | H9: 0 | I9: 4500 | K9: 1500 | L9: 1500 | M9: 1500
A10: 5280 | B10: Travel | D10: -374.77
A11: 5298 | B11: Leadership Grant | D11: 3815.01 | E11: =250*25 -> 6250 | F11: 4750 | G11: 11250 | H11: 0 | I11: 11250 | K11: 10000 | L11: 70000 | M11: 70000 | O11: 40 Chapter Presidents @ $1,750 each to attend Convention (includes early registration fee of $790 and up to 3 nights hotel stay.) Based on $1,666 per person for the 2025 Convention in Orlando, FL.
A12: 5300 | B12: Audio/Visual Rental | C12: 0 | D12: 0 | E12: 3500 | F12: 0 | G12: 3500 | H12: 0 | I12: 2000 | K12: 0 | L12: 0 | M12: 0 | N12: absorbed by Convention
A13: 5335 | B13: Food and Beverage | C13: 0 | D13: 0 | E13: 25000 | F13: 3997.64 | G13: 23000 | H13: 0 | I13: 8000 | K13: 8000 | L13: 0 | M13: 0 | N13: Training at Convention | O13: Food & Beverage are not needed at Convention training any longer.
A14: 5380 | B14: Speaker/Instructors Fee | C14: 11250 | D14: 19363.04 | E14: =6*4000 -> 24000 | F14: 21158.97 | G14: 24000 | H14: 3210 | I14: 24000 | J14: 750 | K14: 15000 | L14: 15000 | M14: 15000 | N14: Annual training, Nuts & Bolts, webinars | O14: Annual training, Nuts & Bolts, webinars
B15: TOTAL EXPENSES | C15: 15362 | D15: 25363.71 | E15: =SUM(E7:E14) -> 63625 | F15: 31039.07 | G15: 66625 | H15: 3210 | I15: =SUM(I7:I14) -> 50000 | J15: =SUM(J7:J14) -> 750 | K15: =SUM(K7:K14) -> 34600 | L15: =SUM(L7:L14) -> 86600 | M15: =SUM(M7:M14) -> 86600
B17: OPERATING PROFIT/LOSS | C17: -15362 | D17: -25363.71 | E17: =SUM(-E15) -> -63625 | F17: -31039.07 | G17: -66625 | H17: -3210 | I17: =-I15 -> -50000 | J17: =-J15 -> -750 | K17: =-K15 -> -34600 | L17: =-L15 -> -86600 | M17: =-M15 -> -86600

Sheet 186-Marketing
A1: Dept 186 Marketing
A2: ACCOUNT | C2: 2021 | D2: 2022 | E2: 2022 | F2: 2023 | G2: 2023 | H2: 2024 | I2: 2024 | J2: 45870 | K2: 2025 | L2: 2026 | M2: 2027 | N2: 2025 Notes | O2: 2026 Notes | P2: 2027 Notes
A3: NUMBER | B3: DESCRIPTION | C3: Budget | D3: ACTUAL | E3: BUDGET | F3: ACTUAL | G3: BUDGET | H3: Actual | I3: Budget | J3: YTD | K3: Budget | L3: Budget | M3: Budget
A4: REVENUES
A5: 3146 | B5: Official Partner | D5: 10000 | E5: 10000 | F5: 4525.2 | G5: 6500 | H5: 7500 | I5: =13*500 -> 6500 | J5: 13000 | K5: =13*500 -> 6500 | L5: =17*500 -> 8500 | M5: 8500 | N5: 13 partners @ $500.00 | O5: 17 partners @500
A6: 3202 | B6: List Sales | C6: 1500 | D6: 0 | E6: 1500 | G6: 1500 | H6: 3652.7 | I6: 2250 | J6: 3130.5 | K6: 2500 | L6: 3200 | M6: =L6*1.03 -> 3296 | O6: Purchase electronic member list | P6: Inc by inflation
A7: 3204 | B7: Consumer Brochures | C7: 0 | D7: 312.5 | E7: 270 | F7: 210 | G7: 270 | H7: 258 | I7: 150 | J7: 45 | K7: 200 | L7: 50 | M7: 50 | O7: Brochures that are for sale
A8: 3206 | B8: Specialty Advertising Items | C8: 0 | D8: 25 | E8: 0 | F8: 670 | G8: 25 | H8: 1015 | I8: 250 | J8: 710 | K8: 500 | L8: 700 | M8: =L8*1.03 -> 721 | O8: Give away items for convention | P8: Inc by inflation
A9: 3222 | B9: Codes/Standards Kits | C9: 50 | D9: 0 | E9: 50 | F9: 10 | G9: 0 | I9: 0 | J9: 10 | L9: 0
A10: 3224 | B10: NARPM Replacement Pins | C10: 50 | D10: 10 | E10: 50 | F10: 0 | G10: 50 | H10: 10 | I10: 0 | L10: 0
A11: 3227 | B11: Outside Marketing Projects | C11: 35000 | D11: 52488.36 | E11: 35000 | F11: 59549.17 | G11: 75000 | H11: 78547.45 | I11: 75000 | J11: 89508.96 | K11: 75000 | L11: 100000 | M11: =L11*1.03 -> 103000 | N11: Multiview | O11: Pulled number from multiview reports | P11: Inc by inflation | Q11: Multiview is a listings site that pays royalties
A12: 3228 | B12: Shipping | D12: 45.94 | E12: 35 | F12: 157.51 | G12: 35 | H12: 187.1 | I12: 75 | J12: 87.5 | K12: 150 | L12: 100 | M12: 100
A13: 3451 | B13: Radio Sponsorship | D13: 150 | E13: 3000 | G13: 3000 | H13: 5583.33 | I13: 3000 | J13: 2666.67 | K13: 4500 | L13: 2500 | M13: =L13*1.03 -> 2575 | O13: Radio sponsorships are down | P13: Inc by inflation
B14: TOTAL REVENUES | C14: =SUM(C6:C13) -> 36600 | D14: 52881.8 | E14: =SUM(E6:E12) -> 36905 | F14: 65121.88 | G14: 76880 | H14: =SUM(H5:H13) -> 96753.58 | I14: =SUM(I5:I13) -> 87225 | J14: =SUM(J5:J13) -> 109158.63 | K14: =SUM(K5:K13) -> 89350 | L14: =SUM(L5:L13) -> 115050 | M14: =SUM(M5:M13) -> 118242
A16: EXPENSES
A17: 5146 | B17: Marketing Committee | H17: 1237.15 | L17: 3000 | M17: 3000 | O17: Travel for committee chair to Conv & B/O
A18: 5152 | B18: Publication Committee | D18: 0 | E18: 2000 | H18: 1104.69 | I18: 3000 | K18: 3000 | L18: 0 | M18: 0
A19: 5210 | B19: Postage | C19: 500 | D19: 485.73 | E19: 550 | F19: 1234.4 | G19: 600 | H19: 696.69 | I19: 900 | J19: 448.95 | K19: 750 | L19: 750 | M19: =L19*1.03 -> 772.5 | O19: Mailing marketing package to chapters
A20: 5225 | B20: Printing | D20: 460.46 | E20: 550 | F20: 10.43 | G20: 550 | H20: 0 | I20: 100 | K20: 50 | L20: 50 | M20: 50
A21: 5226 | B21: Consumer Printing | C21: 100 | D21: 0 | E21: 100 | F21: 0 | G21: 100 | H21: 0 | I21: 0
A22: 5240 | B22: Management Fee | H22: 49194.99 | I22: =49194.95+6964.95 -> 56159.9 | J22: 33780.56 | K22: ='[2]Management Fees'!J12 -> 50670.803 | L22: =K22*1.03 -> 52190.927 | M22: =L22*1.03 -> 53756.655 | O22: 3% annual increase
A23: 5350 | B23: Marketing | J23: 300 | N23: Should be under 186-5368
A24: 5365 | B24: Specialty Advertising Items | C24: 1000 | D24: 466.29 | E24: 1500 | F24: 2492.34 | G24: 2000 | H24: 1412.36 | I24: 2200 | K24: 2000
A25: 5368 | B25: Video/Social Media Marketing | C25: 6000 | D25: 1676.08 | E25: 6000 | F25: 4934.5 | G25: 6000 | H25: 3598 | I25: 4500 | J25: 780 | K25: 9000 | L25: 9000 | M25: =L25*1.03 -> 9270 | N25: Social media marketing and boosting; 1$500 video editing | O25: Social media marketing and boosting; 1$500 video editing | P25: This may be double dipped with the new national media campaign
A26: 5371 | B26: Marketing Projects | C26: 27500 | D26: 21420.01 | E26: 30000 | F26: 40848.1 | G26: 40000 | H26: 60208.58 | I26: 33500 | J26: 20761.7 | K26: 30000 | N26: For Feathr 21,000 for 2024 half of 2-year contract; also, $9,500 to $12,500 extra needed in 2024 for designation follow-me campaign and associated media spends | O26: Waiting in proposal from Scott Oser to provide follow me service in place of current vendor
A27: 5481 | B27: Existing Technology Contracts | D27: 41535.06 | E27: 43000 | G27: 45000 | H27: 40044.2 | I27: 45000 | J27: 24372.15 | K27: 49000 | L27: =(K27*1.03) -> 50470 | M27: =L27*1.03 -> 51984.1 | N27: Mailchimp, Survey Monkey, Zoom, Higher Logic Commmunity Platform | O27: Survey Monkey, Zoom, Doing cuirrent search for vendors to replace the community
A28: 9005 | B28: National brand campaign - Agency of record | L28: 88629 | N28: Agency of record communications support: content production; social media and email content; email program management; asset design (signage, collateral); national campaign management (message development, creative, ad ops, measurement). This assumes a certain degree of work-sharing with NARPM staff (specifically , marketing director, designer, webmaster, executive director, etc.)
A29: 9006 | B29: National brand campaign - Website project | L29: 66700 | N29: Website project: redesign and rebuild website, collaborative approach to content refresh.
A30: 9007 | B30: National brand campaign - campaign | L30: 55575
A31: 9008 | B31: National brand campaign - Paid media budget | L31: 108500 | N31: Paid media budget (out-of-pocket expense, not services) for national campaign focused on membership growth, brand positioning and advocacy.
A32: 9009 | B32: National brand campaign - PR/news media relations | L32: 36000 | N32: (Optional) Limited news media relations services: topical scanning, pitching, placing quotes and op-eds, fielding inquiries.
A33: 5485 | B33: Special Marketing Projects-AS | D33: 0 | E33: 0 | G33: 0 | H33: 8595.3 | I33: 60000 | J33: 18687.27 | K33: 60000 | N33: Hire outside marketing company for national growth campaign | O33: Waiting to see ROI on current campaign
B34: TOTAL EXPENSES | C34: =SUM(C17:C33) -> 35100 | D34: 24508.57 | E34: =SUM(E19:E33) -> 81700 | F34: 49519.77 | G34: 49250 | H34: =SUM(H17:H33) -> 166091.96 | I34: =SUM(I18:I33) -> 205359.9 | J34: =SUM(J17:J33) -> 99130.63 | K34: =SUM(K18:K33) -> 204470.8 | L34: =SUM(L17:L33) -> 470864.93 | M34: =SUM(M18:M33) -> 115833.26
B36: OPERATING PROFIT/LOSS | C36: =C14-C34 -> 1500 | D36: 28373.23 | E36: =E14-E34 -> -44795 | F36: 15602.11 | G36: 27630 | H36: =H14-H34 -> -69338.38 | I36: =I14-I34 -> -118134.9 | J36: =J14-J34 -> 10028 | K36: =K14-K34 -> -115120.8 | L36: =L14-L34 -> -355814.93 | M36: =M14-M34 -> 2408.7448

Sheet 188-Prof Development
A1: Dept 188 PROFESSIONAL DEVELOPMENT COURSES | N1: 2025 Notes | O1: 2026 Notes | P1: 2027 Notes | R1: Generel Note: Budget tabs should have panes frozen so first row and first column stay visible
A2: ACCOUNT | C2: 2021 | D2: 2022 | E2: 2022 | F2: 2023 | G2: 2023 | H2: 2024 | I2: 2024 | J2: 45870 | K2: 2025 | L2: 2026 | M2: 2027
A3: NUMBER | B3: DESCRIPTION | C3: Budget | D3: Actual | E3: BUDGET | F3: ACTUAL | G3: BUDGET | H3: Actuals | I3: Budget | J3: YTD | K3: Budget | L3: Budget | M3: Budget
A4: REVENUES
A5: 3300 | B5: Course Fees | C5: 65645 | D5: 77850 | E5: 88650 | F5: 69925 | G5: 78975 | H5: 34248 | I5: 45000 | J5: 19853 | K5: 34800 | L5: =(768*40)+(192*55) -> 41280 | M5: =(768*45)+(192*60) -> 46080 | N5: 56 classes - 18 avg # students/Finance 25 students | O5: 64 classes - 15 avg # students = 960 (192 non; 768 mem) - 2026 increase reg fee for class to $40 member/$55 nonmember | P5: 2027 increase reg fee for class to $45 member/$60 nonmember
A6: 3302 | B6: Ethics Class | C6: 180 | D6: 250 | E6: 0 | F6: 0 | G6: 250 | H6: 250 | I6: 0 | K6: 0 | L6: 0 | M6: 0
A7: 3310 | B7: On-Line Course Fees | C7: 12362.9 | D7: 18891.7 | E7: 22500 | F7: 15918.4 | G7: 15211.6 | H7: 17242.18 | I7: 16500 | J7: 10015 | K7: 16500 | L7: 15025 | M7: =L7*1.03 -> 15475.75 | N7: =(10015/8)*12 -> 15022.5 | P7: 3% increase
A8: 3315 | B8: Webinars | C8: 310 | D8: 105 | E8: 500 | F8: 0 | G8: 120 | H8: 1150 | I8: 0 | J8: 3220
B9: TOTAL REVENUES | C9: 78497.9 | D9: 97096.7 | E9: =SUM(E5:E8) -> 111650 | F9: 85843.4 | G9: 94556.6 | H9: =SUM(H5:H8) -> 52890.18 | I9: =SUM(I5:I8) -> 61500 | J9: =SUM(J5:J8) -> 33088 | K9: =SUM(K5:K8) -> 51300 | L9: =SUM(L5:L8) -> 56305 | M9: =SUM(M5:M8) -> 61555.75
A11: EXPENSES
A12: 5145 | B12: On-line Education | C12: 17608 | D12: 150 | E12: 6000 | F12: 0 | G12: 500 | H12: 887.5 | I12: 7500 | J12: 537 | K12: 5000 | N12: *This line item is now included in Education - Course Development: In-person, Virtual or Online to provide a more comprehnsive overview of proposed expenses. Please see the line item below.
A13: 5150 | B13: Prof Dev Committee | C13: 104.95 | D13: 1078.56 | E13: 2500 | F13: 535.07 | G13: 2500 | H13: 0 | I13: 2500 | K13: 2500 | L13: 3000 | M13: 3000
A14: 5210 | B14: Postage | C14: 334.69 | D14: 333.64 | E14: 1500 | F14: 314.98 | G14: 500 | H14: 0 | I14: 500 | K14: 250 | L14: =250*1.3 -> 325 | M14: =L14*1.3 -> 422.5
A15: 5220 | B15: Supplies | C15: 0 | D15: 968.93 | E15: 500 | F15: -256.69 | G15: 1500 | H15: 216.2 | I15: 500 | K15: 500 | L15: 250 | M15: =L15*1.3 -> 325
A16: 5225 | B16: Printing | C16: 1373.7 | D16: 967.58 | E16: 1500 | F16: 2127.33 | G16: 750 | H16: 1484.92 | I16: 400 | J16: 399.13 | K16: 1500 | L16: 500 | M16: 500
A17: 5240 | B17: Management Fee | F17: 0 | H17: 75000 | I17: 75000 | J17: 51500 | K17: 77250 | L17: =K17*1.3 -> 100425 | M17: =L17*1.3 -> 130552.5
A18: 5270 | B18: Miscellaneous | C18: 0 | D18: 0 | E18: 250 | F18: 4487.74 | G18: 100 | H18: 0 | I18: 50 | K18: 50 | L18: 50 | M18: 50
A19: 5273 | B19: Course Expenses | C19: 3443.86 | D19: 19622.27 | E19: 2000 | F19: 1384.5 | G19: 2000 | H19: 3754.39 | I19: 500 | J19: 1817.76 | K19: 6000 | L19: 2200 | M19: 2300 | N19: Expenses associated with on site classroom courses | O19: Staff has only had two chapter sponsored classes and both lost money to the chapter
A20: 5276 | B20: Ethics Expenses | C20: 13321 | D20: 13567.5 | E20: 15000 | F20: 13564.35 | G20: 15000 | H20: 16629.5 | I20: 15000 | J20: 13108.5 | K20: 20000 | L20: 20000 | M20: =L20*1.3 -> 26000 | N20: New member ethics course and support staff taking course
A21: 5376 | B21: Ethics Instructor Fees | H21: 405
A22: 5286 | B22: Gift Certificates Redeemed | C22: 300 | D22: 116.5 | E22: 1000 | F22: 741.25 | G22: 500 | H22: 0 | I22: 0 | K22: 0
A23: 5312 | B23: Education - Course Development: In-person, Virtual or Online | C23: 3801 | D23: 5999.5 | E23: 30000 | F23: 22648.5 | G23: 25000 | H23: 14984.25 | I23: 25000 | J23: 4828 | K23: 8000 | L23: 53200 | M23: 29600 | O23: This line item includes 8 3-hour courses dervied from existing 6-hour course content and/or materials. The total cost will be $24,000 (8 x $3,000). The 8 courses that are redeveloped are taught by NARPM and recorded. From those recordings, DL will make edits where necessary and place them in the online learning system. DL's price is $19,200 (8 x $2,400). Also, included in this line item are 2 new content-based courses at a cost of $10,000 (2 X $5,000). | P23: Included in this line item are 4 new content-based courses at a cost of $20,000 (4 X $5,000). Also, these 4 courses are taught by NARPM and recorded. From those recordings, DL will make edits where necessary and place them in the online learning system. DL's price is $9,600 (4 x $2,400).
A24: 5315 | B24: Course Rewrite fee | H24: 1793 | J24: 791
A25: 5350 | B25: Marketing | C25: 0 | D25: 3053 | E25: 0 | F25: 0 | G25: 7500 | H25: 0 | I25: 3000 | N25: marketing for members who hold designations to push out to PM's
A26: 5380 | B26: Speaker/Instructors Fee | C26: 24800 | D26: 29692.19 | E26: 31200 | F26: 27589.9 | G26: 39750 | H26: 16885.4 | I26: 24300 | J26: 15390 | K26: =(50*405)+(6*1050) -> 26550 | L26: =(51*405)+(5*1050) -> 25905 | M26: =(51*405)+(5*1050) -> 25905 | N26: $405 for 3 hr course/$1050 onsite | O26: $405 for 3 hr course/$1050 onsite
A27: 5381 | B27: Speaker/Instructor Expenses | C27: 78.03 | D27: 12742.97 | E27: 15000 | F27: 13775.13 | G27: 14400 | H27: 6637.03 | I27: 8000 | J27: 3160.43 | K27: 12000 | L27: =5*2000 -> 10000 | M27: =L27*1.3 -> 13000 | N27: 6 instructors to teach classes at NARPM events
A28: 5383 | B28: Instructor Training | C28: 9300 | D28: 27413.7 | E28: 20000 | F28: 33113.86 | G28: 32000 | H28: 21518.72 | I28: 35000 | J28: 13921.17 | K28: 30000 | L28: 25000 | M28: 29000 | N28: Incudes cost of third-party trainer and DL participation 8,500. It does not include the NARPM Instructor Expenses.
A29: 5385 | B29: Scholarship | C29: 1235 | D29: 1435 | E29: 1235 | F29: 1435 | G29: 0 | H29: 1120 | I29: 1235 | K29: 1120 | L29: 1200 | M29: 1200
A30: 5390 | B30: Cosponsorship Expense | C30: 4005.75 | D30: 955.65 | E30: 7500 | F30: 2104.09 | G30: 5250 | I30: 0 | K30: 0
A31: 5481 | B31: Existing Technology Contracts | C31: 0 | D31: 558.89 | E31: 2500 | F31: 0 | G31: 2500 | H31: 294.03 | I31: 3500 | J31: 3000 | K31: 1500 | L31: =1500 -> 1500 | M31: =L31*1.3 -> 1950
A32: 9010 | B32: Logo update- Course Materials | L32: 5000 | M32: 1000
A33: 9011 | B33: Legal Hotline | L33: 30000 | M33: 30000 | O33: Please view each proposed legal service as part of a package proposal from national property management attorney Monica Gilroy (available upon request). Legal Hotline: Implementable by the end of January 2026. This service will be priced at a $2500 flat fee per month for year one, to be adjusted up or down in subsequent years based upon yearly volume. Email based responses to members will be provided within 48 hours of receipt. The topics will be limited initially to all Federal Law related questions, for example, Lead Based Paint, Fair Housing, Fair Credit Reporting Act, Anti-Trust, ICE enforcement actions/subpoenas, Federal Subpoenas/Discovery requests, Employment Discrimination, Fair Labor Standards Act (Overtime, Misclassification of Staff). | P33: The flat fee will depend on year one volume.
A34: 9012 | B34: NARPM Best Practices Relating to Liability and Risk Management | L34: 7500 | M34: 1000 | O34: Creation of NARPM Best Practices Relating to Liability and Risk Management. The cost of this Strategic Plan deliverable will be a $7500 flat fee; projected to be available by the beginning of the second quarter of 2026. The Best Practices will be set forth in the form of “Pillars” and are meant to be similar to the NARPM Accounting Standards (and will include an Accounting Pillar which adopts the same). Potential Pillars include Escrow Trust Accounting/Practices, Protecting NPI (Non-Public Personal Information), Onboarding, Habitability, Consumer Complaints, and other topics. This will be collaborative with the Firm drafting the “Pillars” and input coming from NARPM leadership and staff. Best Practices will serve as compliance tools and resources for the NARPM Membership when formulating policies and procedures. The framework will encourage our members to continually improve their practices to ensure financial and operational stability. The “Pillars” can be updated at a flat fee of $1,000 to reflect current industry needs and standards if needed every year or most likely every other year and upon significant industry changes. | P34: To keep the document current, NARPM staff anticipates requesting the $1,000 flat fee update.
A35: 9013 | B35: Legal/Liability Education as an Outside Counsel for National NARPM | L35: 14200 | M35: 14626 | O35: Legal/Liability Education as an Outside Counsel for National NARPM - Quarterly three-day visits to NARPM National Headquarters to develop and create/tape webinars, podcasts, and other educational presentations with NARPM Staff. *14,200 (1,000 per quarter flat fee for 3-day vist plus all travel expenses for 3 nights per quarter (hotel, flight, food, incidentals). *Estimate for travel expenses for 12 days is 10,200.
A36: 9014 | B36: Legal/Liability Education as an Outside Counsel for National NARPM - Chapter Visits | L36: 4000 | M36: 4120 | O36: Legal/Liability Education as an Outside Counsel for National NARPM can be further expanded to have Monica Gilroy travel to NARPM Chapter Meetings, Chapter Conferences or other industry events as a representative of National NARPM when she is not a speaker. While in attendance, Monica Gilroy would hold “office hours” at/before/after those meetings/events to assist NARPM Members with legal issues, compliance and risk management. The cost would be $500 per event plus all travel expenses as stated above. *4,000 (500 per event plus 2500 for all travel expenses for 3 events) Recommend beginning at 3 major regional/state events.
B37: TOTAL EXPENSES | C37: 79705.98 | D37: 118655.88 | E37: =SUM(E12:E31) -> 137685 | F37: 123565.01 | G37: 149750 | H37: =SUM(H12:H31) -> 161609.94 | I37: =SUM(I12:I36) -> 201985 | J37: =SUM(J12:J36) -> 108452.99 | K37: =SUM(K12:K36) -> 192220 | L37: =SUM(L12:L36) -> 304255 | M37: =SUM(M12:M36) -> 314551
B39: OPERATING PROFIT/LOSS | C39: -1208.08 | D39: -21559.18 | E39: =E9-E37 -> -26035 | F39: -37721.61 | G39: -55193.4 | H39: -85087.64 | I39: =I9-I37 -> -140485 | J39: =J9-J37 -> -75364.99 | K39: =K9-K37 -> -140920 | L39: =L9-L37 -> -247950 | M39: =M9-M37 -> -252995.25

Sheet 189-Womens Council
A1: Dept 189 Women's Council | N1: 2025 Notes | O1: 2026 Notes
A2: ACCOUNT | C2: 2021 | D2: 2022 | E2: 2022 | F2: 2023 | G2: 2023 | H2: 2024 | I2: 2024 | J2: 45870 | K2: 2025 | L2: 2026 | M2: 2027
A3: NUMBER | B3: DESCRIPTION | C3: Budget | D3: Actuals | E3: BUDGET | F3: ACTUAL | G3: BUDGET | H3: Actuals | I3: Budget | J3: YTD | K3: Budget | L3: Budget | M3: Budget
A4: REVENUES | O4: Women's Council
A5: 3700 | B5: Registrations | C5: 15160 | D5: 13160 | E5: =((3*35)*40) + (150*150) -> 26700 | F5: 14590 | G5: 26700 | H5: 6985 | I5: 11000 | J5: 110 | K5: 0 | O5: is Sunsetted
A6: 3710 | B6: Sponsorships | C6: 6500 | D6: 18500 | E6: 7500 | F6: 18800 | G6: 7500 | H6: 16515 | I6: 15000 | K6: 10000
B7: TOTAL REVENUES | C7: =SUM(C4:C6) -> 21660 | D7: 31660 | E7: =SUM(E4:E6) -> 34200 | F7: 33390 | G7: 34200 | H7: =SUM(H5:H6) -> 23500 | I7: 26000 | J7: =SUM(J5:J6) -> 110 | K7: =SUM(K5:K6) -> 10000 | L7: =SUM(L5:L6) -> 0 | M7: =SUM(M5:M6) -> 0
A9: EXPENSES
A10: 5210 | B10: Postage | D10: 0 | E10: 250 | F10: 0 | G10: 250 | H10: 0 | I10: 250 | K10: 1000 | N10: conference (increased in case of virtual conf; will not spend if in-person)
A11: 5220 | B11: Supplies | D11: 0 | E11: 100 | F11: 142.47 | G11: 100 | H11: 0 | I11: 100 | K11: 100 | N11: conference
A12: 5225 | B12: Printing | D12: 0 | E12: 500 | F12: 102.41 | G12: 500 | H12: 0 | I12: 500 | K12: 150 | N12: conference
A13: 5270 | B13: Miscellaneous | D13: 0 | F13: 56 | G13: 0 | H13: 2400
A14: 5300 | B14: Audio/Visual Rental | D14: 650.25 | E14: 3000 | F14: 1000 | G14: 3000 | H14: 6434.38 | I14: 3000 | K14: 2000 | N14: conference
A15: 5335 | B15: Food and Beverage | D15: 6736.81 | E15: 5000 | F15: 3098.89 | G15: 5000 | H15: 1000 | I15: 5500
A16: 5380 | B16: Speaker/Instructors Fee | C16: 13100 | D16: 11298.74 | E16: 19750 | F16: 12541 | G16: 19750 | H16: 7050 | I16: 12000 | J16: 1110 | K16: 6000 | N16: speakers for webinars and conference
B17: TOTAL EXPENSES | C17: =SUM(C10:C16) -> 13100 | D17: 18685.8 | E17: =SUM(E10:E16) -> 28600 | F17: 16940.77 | G17: 28600 | H17: =SUM(H10:H16) -> 16884.38 | I17: 21350 | J17: =SUM(J10:J16) -> 1110 | K17: =SUM(K10:K16) -> 9250 | L17: =SUM(L10:L16) -> 0 | M17: =SUM(M10:M16) -> 0
B19: OPERATING PROFIT/LOSS | C19: =C7-C17 -> 8560 | D19: 12974.2 | E19: =E7-E17 -> 5600 | F19: 16449.23 | G19: 5600 | H19: =H7-H17 -> 6615.62 | I19: 4650 | J19: =J7-J17 -> -1000 | K19: =K7-K17 -> 750 | L19: =L7-L17 -> 0 | M19: =M7-M17 -> 0 | N19: Council will ensure if Women's Conference is not held, Council's budgeted profit will be achieved.

Sheet 190-Designations
A1: Dept 190 DESIGNATIONS
A2: ACCOUNT | C2: 2021 | D2: 2022 | E2: 2022 | F2: 2023 | G2: 2023 | H2: 2024 | I2: 2024 | J2: 45870 | K2: 2025 | L2: 2026 | M2: 2027 | N2: 2025 Notes | O2: 2026 Notes | P2: 2027 Notes
A3: NUMBER | B3: DESCRIPTION | C3: Budget | D3: Actuals | E3: Budget | F3: ACTUAL | G3: BUDGET | H3: Actuals | I3: Budget | J3: YTD | K3: Budget | L3: Budget | M3: Budget
A4: REVENUES
A5: 3311 | B5: CSS Certification Fee | C5: 380 | D5: 475 | E5: 456 | F5: 285 | G5: 570 | H5: 285 | I5: =95*4 -> 380 | K5: 570 | L5: 600 | M5: 630
A6: 3312 | B6: RMP Designationn Fees | C6: 5800 | D6: 9400 | E6: 6960 | F6: 9350 | G6: 6960 | H6: 7750 | I6: =55*150 -> 8250 | J6: 7050 | K6: =75*150 -> 11250 | L6: =71*150 -> 10650 | M6: =75*150 -> 11250 | N6: 75 | O6: Total Active Members with the RMP designation is 459, with 71 new projected RMP candidates for 2026 | P6: 75 new projected RMP candidates for 2027
A7: 3314 | B7: MPM Designation Fees | C7: 2750 | D7: 2700 | E7: 3300 | F7: 2500 | G7: 3000 | H7: 3150 | I7: =15*250 -> 3750 | J7: 2125 | K7: =25*250 -> 6250 | L7: =250*15 -> 3750 | M7: =250*17 -> 4250 | N7: 25 | O7: Total Active Members with the MPM designation is 201, with 15 new projected MPM candidates for 2026 | P7: 17 new projected MPM candidates for 2027
A8: 3316 | B8: CRMC Designation Fee | C8: 650 | D8: 955 | E8: 780 | F8: 150 | G8: 780 | H8: 100 | I8: =150*3 -> 450 | J8: 700 | K8: 700 | L8: 1050 | M8: 1400 | N8: 2 | O8: Total Active Members with the CRMC designation is 41 , with 2 new projected CRMC candidates for 2026 | P8: 4 new projected CRMC candidates for 2027
A9: 3317 | B9: CRMC Renewal Fee | C9: 4750 | D9: 4300 | E9: 5700 | F9: 4400 | G9: 5600 | H9: 4000 | I9: 4600 | J9: 3700 | K9: 4100 | L9: 3700 | M9: 4300 | N9: 41 CRMC
A10: 3270 | B10: Designation Miscellaneous Sales | C10: 0 | E10: 0 | F10: 75 | G10: 0 | H10: 0 | I10: 50 | K10: 50 | L10: 0
B11: TOTAL REVENUES | C11: 14330 | D11: 17830 | E11: =SUM(E5:E10) -> 17196 | F11: 16760 | G11: 16910 | H11: =SUM(H5:H10) -> 15285 | I11: =SUM(I5:I10) -> 17480 | J11: =SUM(J5:J10) -> 13575 | K11: =SUM(K5:K10) -> 22920 | L11: =SUM(L5:L10) -> 19750 | M11: =SUM(M5:M10) -> 21830
A13: EXPENSES
A14: 5005 | B14: Awards & Recognition | C14: 1369.29 | D14: 643.73 | E14: 2500 | F14: 793.37 | G14: 1500 | H14: 155.25 | I14: 1200 | J14: 97.41 | K14: 1500 | L14: 1500 | M14: 1500 | O14: Plaques and certificates for designees
A15: 5210 | B15: Postage | C15: 355.5 | D15: 886.63 | E15: 1000 | F15: 808.35 | G15: 1000 | H15: 490.6 | I15: 750 | J15: 162.15 | K15: 1000 | L15: 1000 | M15: 1000 | O15: Postage for plaques
A16: 5225 | B16: Printing | C16: 360.2 | D16: 46.89 | E16: 500 | F16: 0 | G16: 500 | H16: 0 | I16: 400 | K16: 150 | L16: 175 | M16: 200 | O16: Printing designation materials
A17: 5481 | B17: Existing Technology Contracts | C17: 0 | D17: 0 | E17: 5000 | F17: 0 | G17: 10000 | H17: 0 | I17: 7500 | J17: 4249 | K17: 12000 | L17: 5000 | M17: =L17*1.3 -> 6500 | N17: Rebuild designation portal/ In future will be $7000 a year | O17: Maintenance Designation Portal through SALT and updates
B18: TOTAL EXPENSES | C18: 2084.99 | D18: 1577.25 | E18: =SUM(E14:E17) -> 9000 | F18: 1601.72 | G18: 13000 | H18: =SUM(H14:H17) -> 645.85 | I18: =SUM(I14:I17) -> 9850 | J18: =SUM(J14:J17) -> 4508.56 | K18: =SUM(K14:K17) -> 14650 | L18: =SUM(L14:L17) -> 7675 | M18: =SUM(M14:M17) -> 9200
B20: OPERATING PROFIT/LOSS | C20: 12245.01 | D20: =D11-D18 -> 16252.75 | E20: =E11-E18 -> 8196 | F20: 15158.28 | G20: 3910 | H20: =H11-H18 -> 14639.15 | I20: =I11-I18 -> 7630 | J20: =J11-J18 -> 9066.44 | K20: =K11-K18 -> 8270 | L20: =L11-L18 -> 12075 | M20: =M11-M18 -> 12630

Sheet 192-Res Resource
A1: Dept 192 RESIDENTIAL RESOURCE
A2: ACCOUNT | C2: 2021 | D2: 2022 | E2: 2022 | F2: 2023 | G2: 2023 | H2: 2024 | I2: 2024 | J2: 45870 | K2: 2025 | L2: 2026 | M2: 2027 | N2: 2025 Notes | O2: 2026 Notes
A3: NUMBER | B3: DESCRIPTION | C3: Budget | D3: ACTUAL | E3: BUDGET | F3: ACTUAL | G3: BUDGET | H3: Actuals | I3: Budget | J3: YTD | K3: Budget | L3: Budget | M3: Budget
A4: REVENUES
A5: 3146 | B5: Official Partner | C5: 45000 | D5: 50000 | E5: 50000 | F5: 65000 | G5: 65000 | H5: 70000 | I5: =12*5000 -> 60000 | J5: 75000 | K5: =13*5000 -> 65000 | L5: =17*5000 -> 85000 | M5: =17*5000 -> 85000 | N5: estimated 12 partners at $5,000 per partner | O5: 17 partners @$5000
A6: 3401 | B6: Newsletter Advertising | C6: 50000 | D6: 29140.55 | E6: 40000 | F6: 10340.5 | G6: 10000 | H6: 7120 | I6: 10000 | J6: 1449.2 | K6: 6000 | L6: 5000 | M6: =L6*1.03 -> 5150 | N6: Work on marketing to vendors | O6: Work building advertisers
B7: TOTAL REVENUES | C7: =SUM(C5:C6) -> 95000 | D7: 79140.55 | E7: =SUM(E5:E6) -> 90000 | F7: 75340.5 | G7: 75000 | H7: =SUM(H5:H6) -> 77120 | I7: =SUM(I5:I6) -> 70000 | J7: =SUM(J5:J6) -> 76449.2 | K7: =SUM(K5:K6) -> 71000 | L7: =SUM(L5:L6) -> 90000 | M7: =SUM(M5:M6) -> 90150
A9: EXPENSES
A10: 5212 | B10: Newsletter Postage | C10: 15000 | D10: 12588.02 | E10: 20000 | F10: 17288.92 | G10: 20000 | H10: 11016.76 | I10: 20000 | J10: 7552.86 | K10: 12000 | L10: 13500 | M10: =L10*1.03 -> 13905 | O10: Increase postage cost
A11: 5225 | B11: Printing | C11: 100 | D11: 36.21 | E11: 100 | F11: 0 | G11: 100 | H11: 45.33 | I11: 100 | J11: 38.21 | K11: 100 | L11: 100 | M11: 100
A12: 5345 | B12: Newsletter Production/Printing | C12: 31000 | D12: 21767.65 | E12: 31000 | F12: 38397.4 | G12: 31000 | H12: 33154.56 | I12: 31405 | J12: 22058.43 | K12: 35000 | L12: 35000 | M12: =L12*1.03 -> 36050 | N12: Paper costs have increased since mid-year due to inflation | O12: inc by inflation
A13: 5371 | B13: Marketing Projects | C13: 3500 | D13: 540 | E13: 0 | F13: 300 | G13: 0 | H13: 0 | I13: 0
B14: TOTAL EXPENSES | C14: =SUM(C10:C13) -> 49600 | D14: 34931.88 | E14: =SUM(E10:E13) -> 51100 | F14: 55986.32 | G14: 51100 | H14: =SUM(H10:H13) -> 44216.65 | I14: =SUM(I10:I13) -> 51505 | J14: =SUM(J10:J13) -> 29649.5 | K14: =SUM(K10:K13) -> 47100 | L14: =SUM(L10:L13) -> 48600 | M14: =SUM(M10:M13) -> 50055
B16: OPERATING PROFIT/LOSS | C16: =SUM(C7-C14) -> 45400 | D16: 44208.67 | E16: =SUM(E7-E14) -> 38900 | F16: 19354.18 | G16: 23900 | H16: =H7-H14 -> 32903.35 | I16: =I7-I14 -> 18495 | J16: =J7-J14 -> 46799.7 | K16: =K7-K14 -> 23900 | L16: =L7-L14 -> 41400 | M16: =M7-M14 -> 40095

Sheet 195-Capitol Summit
A1: Dept 195 Capitol Summit | N1: 2025 Notes | O1: 2026 Notes
A2: ACCOUNT | C2: 2021 | D2: 2022 | E2: 2022 | F2: 2023 | G2: 2023 | H2: 2024 | I2: 2024 | J2: 2025 AUG | K2: 2025 | L2: 2026 | M2: 2027
A3: NUMBER | B3: DESCRIPTION | C3: Budget | D3: Actuals | E3: BUDGET | F3: ACTUAL | G3: BUDGET | H3: Actuals | I3: Budget | J3: YTD | K3: Budget | L3: Budget | M3: Budget
A4: REVENUES
A5: 3700 | B5: Registrations | C5: 180 | D5: 8825 | E5: 19500 | F5: 8875 | G5: 29500 | H5: 51425 | I5: 47500 | J5: 30975 | K5: =475*125 -> 59375 | L5: =475*125 -> 59375 | N5: $475 @ 125
A6: 3710 | B6: Sponsorships | C6: 25000 | D6: 20000 | E6: 22500 | F6: 26000 | G6: 24200 | H6: 35600 | I6: 40000 | J6: 45150 | K6: 33500 | L6: 55000 | N6: (35 - partners; 10 - other sponsorships) | O6: 25 exhibitor booths at $2,000 each.
B7: TOTAL REVENUES | C7: 25180 | D7: 28825 | E7: =SUM(E5:E6) -> 42000 | F7: 34875 | G7: 53700 | H7: =SUM(H5:H6) -> 87025 | I7: =SUM(I5:I6) -> 87500 | J7: =SUM(J5:J6) -> 76125 | K7: =SUM(K5:K6) -> 92875 | L7: =SUM(L5:L6) -> 114375
A9: EXPENSES
A10: 5210 | B10: Postage | C10: 0 | D10: 158.66 | E10: 250 | F10: 0 | G10: 250 | H10: 628.18 | I10: 250 | J10: 2390.55 | K10: 700 | L10: 2400 | O10: Shipping cost
A11: 5220 | B11: Supplies | C11: 0 | D11: 0 | E11: 250 | F11: 0 | G11: 250 | H11: 34.02 | I11: 250 | K11: 50 | L11: 100
A12: 5221 | B12: Registration Bag | C12: 0 | D12: 0 | E12: 500 | F12: 0 | G12: 500 | H12: 124.5 | K12: 0 | L12: 0
A13: 5225 | B13: Printing | C13: 0 | D13: 0 | E13: 500 | F13: 348.33 | G13: 500 | H13: 196.7 | I13: 500 | J13: 307.22 | K13: 200 | L13: 350
A14: 5240 | B14: Management Fee | C14: 4120 | D14: 4243.6 | E14: 4244 | F14: 4370.88 | G14: 4370.91 | H14: 4502 | I14: 4502.04 | J14: 4952.24 | K14: 4952.24 | L14: 4952.24
A15: 5245 | B15: Attrition Fee | J15: 3560.72
A16: 5270 | B16: Miscellaneous | C16: 0 | D16: 2500 | E16: 250 | F16: 0 | G16: 2500 | H16: 1920.99 | I16: 500 | K16: 1500 | L16: 1500
A17: 5280 | B17: Travel | C17: 0 | D17: 4477.89 | E17: 5500 | F17: 6150.61 | G17: 6000 | H17: 6837.8 | I17: 10000 | J17: 7240.35 | K17: 9000 | L17: 9000
A18: 5300 | B18: Audio/Visual Rental | C18: 0 | D18: 1489.06 | E18: 4750 | F18: 2391.75 | G18: 2000 | H18: 5661.34 | I18: 4000 | J18: 5530.16 | K18: 5500 | L18: 8350 | O18: Estimate is 6,000 + 26% AV charge + 10% sales tax
A19: 5323 | B19: Signage | C19: 0 | D19: 0 | E19: 500 | F19: 0 | G19: 1000 | H19: 0 | I19: 500 | J19: 0 | K19: 100 | L19: 100
A20: 5335 | B20: Food and Beverage | C20: 0 | D20: 24184.03 | E20: 20350 | F20: 19203.3 | G20: 25000 | H20: 47403.03 | I20: 43320 | J20: 49987.04 | K20: 52000 | L20: 81600 | O20: Minimum is 60,000 + 18% house service charge +8% staff service + 10% sales tax
A21: 5370 | B21: Facility Charge | C21: 0 | D21: 275 | E21: 1000 | F21: 0 | G21: 1000 | H21: 6332.25 | I21: 2800 | J21: 6500 | K21: 6500 | L21: 1500 | O21: Hotel FEDEX holding charges
A22: 5380 | B22: Speaker | H22: 1380.76 | I22: 6000 | K22: 4500 | L22: 1500
A23: 5381 | B23: Speaker Travel | H23: 2587.64 | I23: 1250 | K23: 2500 | L23: 1500
B24: TOTAL EXPENSES | C24: 4120 | D24: 37328.24 | E24: =SUM(E10:E21) -> 38094 | F24: 32464.87 | G24: 43370.91 | H24: =SUM(H10:H23) -> 77609.21 | I24: =SUM(I10:I23) -> 73872.04 | J24: =SUM(J10:J23) -> 80468.28 | K24: =SUM(K10:K23) -> 87502.24 | L24: =SUM(L10:L23) -> 112852.24
B26: OPERATING PROFIT/LOSS | C26: 21060 | D26: -8503.24 | E26: =E7-E24 -> 3906 | F26: 2410.13 | G26: 10329.09 | H26: =H7-H24 -> 9415.79 | I26: =I7-I24 -> 13627.96 | J26: =J7-J24 -> -4343.28 | K26: =K7-K24 -> 5372.76 | L26: =L7-L24 -> 1522.76
A28: 2024 Travel Details:
A29: 5 staff; 3 chairs
A30: Rooms $6,000
A31: Travel $1,000 – staff train
A32: Food $1,500

Sheet 198-Broker Owner
A1: Dept 198 Broker Owner Conference & Expo | N1: Notes from 2025 | O1: Notes for 2026
A2: ACCOUNT | C2: 2021 | D2: 2022 | E2: 2022 | F2: 2023 | G2: 2023 | H2: 2024 | I2: 2024 | J2: 2025 Aug | K2: 2025 | L2: 2026 | M2: 2027
A3: NUMBER | B3: DESCRIPTION | C3: Budget | D3: Actuals | E3: BUDGET | F3: ACTUAL | G3: BUDGET | H3: Actuals | I3: Budget | J3: YTD | K3: Budget | L3: Budget | M3: Budget
A4: REVENUES
A5: 3146 | B5: Official Partner | C5: 25000 | D5: 30250 | E5: 25000 | F5: 45000 | G5: 39000 | H5: 41350 | I5: =13*3000+2500 -> 41500 | J5: 56000 | K5: =13*3000 -> 39000 | L5: 46500 | M5: 60000 | N5: 13 Partners @3000 | O5: 17 Partners @3,575.00 (partner agreement value) - this does not include the premier partnership
A6: 3400 | B6: Advertising | C6: 2285 | D6: 1017.5 | E6: 2250 | F6: 1485 | G6: 1000 | H6: 550 | I6: 1250 | J6: 160 | K6: 500 | L6: 200 | M6: 200
A7: 3700 | B7: Registrations | C7: 163682 | D7: 432810 | E7: 345000 | F7: 483985 | G7: 395000 | H7: 542430 | I7: =600*790 -> 474000 | J7: 627140 | K7: =650*790 -> 513500 | L7: 581000 | M7: 581000 | N7: 600 attendees @ $790 (560 in 2023) | O7: 700 attendees @ $830 (710 in 2025) - this reflects a 5% increase (proposed by committee chair) to reflect the increase in value.
A8: 9015 | B8: Cunningham session | K8: =250*150 -> 37500 | L8: 37500 | M8: 37500 | O8: 150 registrants at $250
A9: 3710 | B9: Sponsorships | C9: 11500 | D9: 12000 | E9: 12000 | F9: 18900 | G9: 12000 | H9: 36400 | I9: 16000 | J9: 47200 | K9: 25000 | L9: 100000 | M9: 100000 | N9: Other sponsorships (no coffee break or wifi sponsor) | O9: Aiming for 100,000 - 150,000
A10: 3760 | B10: Exhibit Booths | C10: 68625 | D10: 108985 | E10: 105000 | F10: 99350 | G10: 82250 | H10: 219900 | I10: =2250*55 -> 123750 | J10: 303065 | K10: =100*2600 -> 260000 | L10: 290000 | M10: 290000 | N10: 100 booths for sale with 2 meal tickets | O10: I recommend an increase in booth prices as well - not reflected here.
B11: TOTAL REVENUES | C11: 271092 | D11: 585062.5 | E11: =SUM(E5:E10) -> 489250 | F11: 648720 | G11: 529250 | H11: =SUM(H5:H10) -> 840630 | I11: =SUM(I5:I10) -> 656500 | J11: =SUM(J5:J10) -> 1033565 | K11: =SUM(K5:K10) -> 875500 | L11: =SUM(L5:L10) -> 1055200 | M11: =SUM(M5:M10) -> 1068700
A13: EXPENSES
A14: 5210 | B14: Postage | C14: 0 | D14: 2.11 | E14: 250 | F14: 0 | G14: 150 | H14: 0 | I14: 50 | J14: 76.84 | K14: 50 | L14: 100 | M14: 100
A15: 5211 | B15: Shipping | C15: 4050.23 | D15: 4325.32 | E15: 5500 | F15: 5729.13 | G15: 5500 | H15: 6791.91 | I15: 5500 | J15: 4824.85 | K15: 6800 | L15: 5500 | M15: 6000 | O15: Expecting an increase in shipping costs.
A16: 5220 | B16: Supplies | C16: 0 | D16: 1601.74 | E16: 3000 | F16: 2726.11 | G16: 3000 | H16: 696.34 | I16: 3000 | J16: 3337.41 | K16: 1000 | L16: 1250 | M16: 1200
A17: 5221 | B17: Registration Bags | H17: 800.5 | L17: 15000 | M17: 15000 | O17: Room drop gift idea - from NARPM
A18: 5225 | B18: Printing | C18: 1396.97 | D18: 1593.36 | E18: 0 | F18: 1114.69 | G18: 2000 | H18: 2463.13 | I18: 1500 | J18: 645.66 | K18: 2600 | L18: 500 | M18: 500
A19: 5230 | B19: Insurance | C19: 0 | D19: 4229.47 | E19: 1500 | F19: 0 | G19: 4500 | H19: 2886.88 | I19: 5000 | K19: 3500 | L19: 3500 | M19: 3500
A20: 5270 | B20: Miscellaneous | C20: 1088.65 | D20: 2157.45 | E20: 3000 | F20: 2104.53 | G20: 3000 | H20: 0 | I20: 2500 | J20: 7.82 | K20: 1000 | L20: 5000 | M20: 5000 | O20: gamification prizes (New from committee)
A21: 5280 | B21: Travel | C21: 6056.57 | D21: 0 | E21: 1000 | F21: 8536.29 | G21: 14400 | H21: 7521.6 | I21: 10000 | J21: 16198.43 | K21: 11000 | L21: 15000 | M21: 15000 | N21: 7 staff travel | O21: 7 staff travel - expecting travel expenses to rise.
A22: 5300 | B22: Audio/Visual Rental | C22: 105996.23 | D22: 7196.36 | E22: 8500 | F22: 82756.93 | G22: 8500 | H22: 116477.45 | I22: 100000 | J22: 155349.41 | K22: 125000 | L22: 125000 | M22: 125000 | O22: Possibly need to put out RFPs for this - will know more after convention.
A23: 5305 | B23: Convention Video Taping Exp | C23: 30000 | D23: 69958.39 | E23: 75000 | F23: 20570.72 | G23: 75000 | H23: 17374.26 | I23: 25000 | J23: 18640.3 | K23: 21000 | L23: 20000 | M23: 20000 | O23: Will get quote from Everessi
A24: 5316 | B24: Temporary Service | C24: 0 | D24: 7500 | E24: 5000 | F24: 6265.19 | G24: 7500 | H24: 9293.21 | I24: 6500 | J24: 10905.36 | K24: 9500 | L24: 12000 | M24: 12000 | N24: 3rd party hotel contractor | O24: 3rd party hotel contractor
A25: 5323 | B25: Signage | C25: 1403.63 | D25: 0 | E25: 500 | F25: 0 | G25: 1500 | H25: 1635.3 | I25: 1500 | J25: 0 | K25: 1700 | L25: 6000 | M25: 6000 | O25: More & better signage, banners, etc.
A26: 5328 | B26: Exhibit Expenses | C26: 2834.23 | D26: 260.22 | E26: 2000 | F26: 12503.04 | G26: 2000 | H26: 15020.95 | I26: 20000 | J26: 27569.23 | K26: 20000 | L26: 25000 | M26: 25000
A27: 5335 | B27: Food and Beverage | C27: 44105.73 | D27: 12067.25 | E27: 15000 | F27: 391278.06 | G27: 280000 | H27: 443569.83 | I27: =(600*450)+(280*300) -> 354000 | J27: 532795.83 | K27: 500000 | L27: 525000 | M27: 525000 | O27: Minimum is 275,000 + 26% service fee + 10.75% sales tax.
A28: 5350 | B28: Marketing | D28: 277054.01 | F28: 554.08 | G28: 0 | H28: 0 | I28: 1500 | L28: 4500 | M28: 4500 | N28: In Marketing Budget | O28: I addition to the marketing budget. Committee looking to do more in terms of marketing.
A29: 5370 | B29: Facility Charge | C29: 148.89 | D29: 0 | E29: 281000 | F29: 4469.9 | G29: 15000 | H29: 1562.4 | I29: 5000 | J29: 7210.9 | K29: 2500 | L29: 3500 | M29: 3500 | N29: Room Rental Fee
A30: 5380 | B30: Speaker/Instructors Fee | C30: 79165.75 | D30: 41250 | E30: 60000 | F30: 12500 | G30: 3000 | H30: 48700 | I30: =(7500*3)+(1500*15)+22500 -> 67500 | J30: 74000 | K30: =(3*7500)+(18*1500)+31000+15000 -> 95500 | L30: 150000 | M30: 150000 | N30: 3@$7500; 18@$1500; outside $31000 Marc Cunningham $15000 | O30: Committee is looking at high-profile speakers. They are going to have some sessions sponsored.
A31: 5381 | B31: Speaker/Instructor Expenses | C31: 0 | D31: 1510.69 | E31: 500 | F31: 37065.9 | G31: 60000 | H31: 3185.9 | I31: 12500 | J31: 5054.41 | K31: 7500 | L31: 20000 | M31: 20000 | N31: Outside Speakers Travel Expenses | O31: Increasing - high profile speakers have more expensive travel requirements
A32: 5510 | B32: Advertising Sales Commission | C32: 187 | E32: 6000 | F32: 0 | G32: 6000 | H32: 0 | I32: 2500 | K32: 0
A33: 9016 | B33: Welcome Reception | L33: 100000 | M33: 50000 | O33: additional charge (or increase) in registration. Committee working to get 50,000 in sponsorships for this + coordinating with Partners. Request from committee.
A34: 5320 | B34: Entertainment | L34: 20000 | M34: 20000 | O34: Request from committee.
A35: 5512 | B35: CVENT - Broker Owner | J35: 38957.77 | K35: =18761+7500 -> 26261 | L35: 40000 | M35: 40000
A36: 9017 | B36: Wi-Fi | L36: 15000 | M36: 15000
